<?xml version="1.0" ?>
<!-- =================================================================================== -->
<!-- |    This document was autogenerated by xacro from dummy1.urdf.xacro              | -->
<!-- |    EDITING THIS FILE BY HAND IS NOT RECOMMENDED                                 | -->
<!-- =================================================================================== -->
<robot name="dummy1">
  <material name="Gray">
    <color rgba="0.5 0.5 0.5 1.0"/>
  </material>
  <material name="Green">
    <color rgba="0.0 1.0 0.0 1.0"/>
  </material>
  <link name="base_footprint"/>
  <link name="base_link">
    <visual>
      <origin rpy="0.0 0.0 0.0" xyz="0.0 0.0 0.0"/>
      <geometry>
        <box size="0.3 0.13 0.039"/>
      </geometry>
      <material name="Cyan">
        <color rgba="0 1.0 1.0 1.0"/>
      </material>
    </visual>
  </link>
  <gazebo reference="base_link">
    <material>Gazebo/Black</material>
  </gazebo>
  <joint name="base_joint" type="fixed">
    <parent link="base_footprint"/>
    <child link="base_link"/>
    <origin rpy="0.0 0.0 0.0" xyz="0.0 0.0 0.0615"/>
  </joint>
  <link name="laser">
    <visual>
      <!-- <origin xyz="0.0 0.0 0.0" /> -->
      <geometry>
        <cylinder length="0.04" radius="0.0325"/>
      </geometry>
    </visual>
  </link>
  <joint name="laser_joint" type="fixed">
    <origin xyz="0.065 0.0 0.0960"/>
    <parent link="base_link"/>
    <child link="laser"/>
  </joint>
  <gazebo reference="laser">
    <sensor name="lidar" type="ray">
      <always_on>true</always_on>
      <visualize>true</visualize>
      <update_rate>10</update_rate>
      <ray>
        <scan>
          <horizontal>
            <samples>5000</samples>
            <resolution>0.500000</resolution>
            <min_angle>-3.14159</min_angle>
            <max_angle>3.14159</max_angle>
          </horizontal>
        </scan>
        <range>
          <min>0.12</min>
          <max>10.0</max>
          <resolution>0.015</resolution>
        </range>
        <noise>
          <type>gaussian</type>
          <mean>0.0</mean>
          <stddev>0.01</stddev>
        </noise>
      </ray>
      <plugin filename="libgazebo_ros_ray_sensor.so" name="scan">
        <output_type>sensor_msgs/LaserScan</output_type>
        <frame_name>laser</frame_name>
      </plugin>
    </sensor>
  </gazebo>
  <gazebo reference="laser">
    <mu1>0.01</mu1>
    <mu2>0.01</mu2>
    <material>Gazebo/Blue</material>
  </gazebo>
  <link name="driveRwhl_l_link">
    <visual>
      <origin rpy="1.5707963267948966 0.0 0.0" xyz="0.0 0.0 0.0"/>
      <geometry>
        <cylinder length="0.035" radius="0.0365"/>
      </geometry>
      <material name="Gray"/>
    </visual>
  </link>
  <joint name="driveRwhl_l_joint" type="continuous">
    <parent link="base_link"/>
    <child link="driveRwhl_l_link"/>
    <axis xyz="0.0 1.0 0.0"/>
    <origin rpy="0.0 0.0 0.0" xyz="-0.0915 0.085 -0.025"/>
  </joint>
  <link name="driveRwhl_r_link">
    <visual>
      <origin rpy="1.5707963267948966 0.0 0.0" xyz="0.0 0.0 0.0"/>
      <geometry>
        <cylinder length="0.035" radius="0.0365"/>
      </geometry>
      <material name="Gray"/>
    </visual>
  </link>
  <joint name="driveRwhl_r_joint" type="continuous">
    <parent link="base_link"/>
    <child link="driveRwhl_r_link"/>
    <axis xyz="0.0 1.0 0.0"/>
    <origin rpy="0.0 0.0 0.0" xyz="-0.0915 -0.085 -0.025"/>
  </joint>
  <link name="steer_link">
    <visual>
      <origin xyz="-0.02 0.0 0.0"/>
      <geometry>
        <box size="0.03 0.01995 0.005"/>
      </geometry>
      <material name="Gray"/>
    </visual>
  </link>
  <joint name="steer_joint" type="revolute">
    <origin rpy="0.0 0.0 0.0" xyz="0.0 0.0 0.0"/>
    <parent link="base_link"/>
    <child link="steer_link"/>
    <axis xyz="0.0 0.0 1"/>
    <limit effort="100.0" lower="-0.5" upper="0.5" velocity="10.0"/>
  </joint>
  <link name="front_L_bar_link">
    <visual>
      <origin rpy="0.0 0.0 0.0" xyz="-0.02 0.0 0.0"/>
      <geometry>
        <box size="0.03 0.01995 0.005"/>
      </geometry>
      <material name="Green"/>
    </visual>
  </link>
  <link name="front_R_bar_link">
    <visual>
      <origin rpy="0.0 0.0 0.0" xyz="-0.02 0.0 0.0"/>
      <geometry>
        <box size="0.03 0.01995 0.005"/>
      </geometry>
      <material name="Green"/>
    </visual>
  </link>
  <joint name="front_R_bar_joint" type="revolute">
    <origin rpy="0.0 0.0 0.0" xyz="0.0 -0.06 0.0"/>
    <parent link="base_link"/>
    <child link="front_R_bar_link"/>
    <axis xyz="0.0 0.0 1"/>
    <limit effort="100" lower="-0.5" upper="0.5" velocity="10.0"/>
  </joint>
  <joint name="front_L_bar_joint" type="revolute">
    <origin rpy="0.0 0.0 0.0" xyz="0.0 0.06 0.0"/>
    <parent link="base_link"/>
    <child link="front_L_bar_link"/>
    <axis xyz="0.0 0.0 1"/>
    <limit effort="100" lower="-0.5" upper="0.5" velocity="10.0"/>
  </joint>
  <link name="front_L_wheel_link">
    <visual>
      <origin rpy="1.5707963267948966 0.0 0.0"/>
      <geometry>
        <cylinder length="0.035" radius="0.0365"/>
      </geometry>
      <material name="Gray"/>
    </visual>
  </link>
  <joint name="front_left_wheel_joint" type="continuous">
    <parent link="front_L_bar_link"/>
    <child link="front_L_wheel_link"/>
    <axis xyz="0.0 1.0 0.0"/>
    <origin rpy="0.0 0.0 0.0" xyz="0.0915 0.022500000000000006 -0.025"/>
  </joint>
  <link name="front_R_wheel_link">
    <visual>
      <origin rpy="1.5707963267948966 0 0"/>
      <geometry>
        <cylinder length="0.035" radius="0.0365"/>
      </geometry>
      <material name="Gray"/>
    </visual>
  </link>
  <joint name="front_right_wheel_joint" type="continuous">
    <parent link="front_R_bar_link"/>
    <child link="front_R_wheel_link"/>
    <axis xyz="0.0 1.0 0.0"/>
    <origin rpy="0.0 0.0 0.0" xyz="0.0915 -0.022500000000000006 -0.025"/>
  </joint>
  <link name="ackermann_bar_link">
    <visual>
      <geometry>
        <box size="0.015 0.15 0.01"/>
      </geometry>
      <material name="Green"/>
    </visual>
  </link>
  <joint name="ackermann_joint" type="revolute">
    <limit effort="100" lower="-0.5" upper="0.5" velocity="10"/>
    <axis xyz="0.0 0.0 1"/>
    <parent link="steer_link"/>
    <child link="ackermann_bar_link"/>
    <origin xyz="-0.04 0.0 0.0"/>
  </joint>
  <gazebo>
    <plugin filename="libgazebo_ros_ackermann_drive.so" name="gazebo_ros_ackerman_drive">
      <update_rate>100.0</update_rate>
      <front_left_joint>front_left_wheel_joint</front_left_joint>
      <front_right_joint>front_right_wheel_joint</front_right_joint>
      <rear_left_joint>driveRwhl_l_joint</rear_left_joint>
      <rear_right_joint>driveRwhl_r_joint</rear_right_joint>
      <left_steering_joint>front_L_bar_joint</left_steering_joint>
      <right_steering_joint>front_R_bar_joint</right_steering_joint>
      <max_steer>0.5233</max_steer>
      <max_steering_angle>2.0944</max_steering_angle>
      <max_speed>40</max_speed>
      <publish_odom>true</publish_odom>
      <publish_odom_tf>true</publish_odom_tf>
      <publish_wheel_tf>true</publish_wheel_tf>
      <odometry_frame>odom</odometry_frame>
      <robot_base_frame>base_link</robot_base_frame>
    </plugin>
  </gazebo>
  <link name="imu_link">
    <visual>
      <geometry>
        <box size="0.01 0.01 0.01"/>
      </geometry>
    </visual>
    <collision>
      <geometry>
        <box size="0.01 0.01 0.01"/>
      </geometry>
    </collision>
  </link>
  <joint name="imu_joint" type="fixed">
    <parent link="base_link"/>
    <child link="imu_link"/>
    <origin xyz="0.035 0.0 0.05"/>
  </joint>
  <gazebo reference="imu_link">
    <gravity>true</gravity>
    <sensor name="imu" type="imu">
      <always_on>true</always_on>
      <update_rate>50.0</update_rate>
      <visualize>true</visualize>
      <imu>
        <orientation>
          <x>
            <noise type="gaussian">
              <mean>0.0</mean>
              <stddev>2e-3</stddev>
            </noise>
          </x>
          <y>
            <noise type="gaussian">
              <mean>0.0</mean>
              <stddev>2e-3</stddev>
            </noise>
          </y>
          <z>
            <noise type="gaussian">
              <mean>0.0</mean>
              <stddev>2e-3</stddev>
            </noise>
          </z>
        </orientation>
        <angular_velocity>
          <x>
            <noise type="gaussian">
              <mean>0.0</mean>
              <stddev>2e-4</stddev>
            </noise>
          </x>
          <y>
            <noise type="gaussian">
              <mean>0.0</mean>
              <stddev>2e-4</stddev>
            </noise>
          </y>
          <z>
            <noise type="gaussian">
              <mean>0.0</mean>
              <stddev>2e-4</stddev>
            </noise>
          </z>
        </angular_velocity>
        <linear_acceleration>
          <x>
            <noise type="gaussian">
              <mean>0.0</mean>
              <stddev>1.7e-2</stddev>
            </noise>
          </x>
          <y>
            <noise type="gaussian">
              <mean>0.0</mean>
              <stddev>1.7e-2</stddev>
            </noise>
          </y>
          <z>
            <noise type="gaussian">
              <mean>0.0</mean>
              <stddev>1.7e-2</stddev>
            </noise>
          </z>
        </linear_acceleration>
      </imu>
      <plugin filename="libgazebo_ros_imu_sensor.so" name="dummy1_imu">
        <initial_orientation_as_reference>false</initial_orientation_as_reference>
        <frame_name>imu_link</frame_name>
      </plugin>
    </sensor>
  </gazebo>
</robot>
